Workbook

Sheet Summary
A1: REIMBURSEMENT SUMMARY
A2: Gerald "Ned" Pearson — bills in "House Bills" folder. Prepared August 29, 2026.
A4: Category | B4: Total Billed | C4: % She Owes | D4: She Owes
A5: Utilities | B5: =SUMIF(Ledger!$C$4:$C$112,A5,Ledger!$E$4:$E$112) | C5: =IFERROR(INDEX(Settings!$B$5:$B$18,MATCH(A5,Settings!$A$5:$A$18,0)),0) | D5: =SUMIF(Ledger!$C$4:$C$112,A5,Ledger!$H$4:$H$112)
A6: Pool | B6: =SUMIF(Ledger!$C$4:$C$112,A6,Ledger!$E$4:$E$112) | C6: =IFERROR(INDEX(Settings!$B$5:$B$18,MATCH(A6,Settings!$A$5:$A$18,0)),0) | D6: =SUMIF(Ledger!$C$4:$C$112,A6,Ledger!$H$4:$H$112)
A7: Storage | B7: =SUMIF(Ledger!$C$4:$C$112,A7,Ledger!$E$4:$E$112) | C7: =IFERROR(INDEX(Settings!$B$5:$B$18,MATCH(A7,Settings!$A$5:$A$18,0)),0) | D7: =SUMIF(Ledger!$C$4:$C$112,A7,Ledger!$H$4:$H$112)
A8: Cleaning | B8: =SUMIF(Ledger!$C$4:$C$112,A8,Ledger!$E$4:$E$112) | C8: =IFERROR(INDEX(Settings!$B$5:$B$18,MATCH(A8,Settings!$A$5:$A$18,0)),0) | D8: =SUMIF(Ledger!$C$4:$C$112,A8,Ledger!$H$4:$H$112)
A9: Lawn/Yard | B9: =SUMIF(Ledger!$C$4:$C$112,A9,Ledger!$E$4:$E$112) | C9: =IFERROR(INDEX(Settings!$B$5:$B$18,MATCH(A9,Settings!$A$5:$A$18,0)),0) | D9: =SUMIF(Ledger!$C$4:$C$112,A9,Ledger!$H$4:$H$112)
A10: AT&T Business | B10: =SUMIF(Ledger!$C$4:$C$112,A10,Ledger!$E$4:$E$112) | C10: flat $100/mo | D10: =SUMIF(Ledger!$C$4:$C$112,A10,Ledger!$H$4:$H$112)
A11: School/Tuition | B11: =SUMIF(Ledger!$C$4:$C$112,A11,Ledger!$E$4:$E$112) | C11: =IFERROR(INDEX(Settings!$B$5:$B$18,MATCH(A11,Settings!$A$5:$A$18,0)),0) | D11: =SUMIF(Ledger!$C$4:$C$112,A11,Ledger!$H$4:$H$112)
A12: Medical/Dental/Vision | B12: =SUMIF(Ledger!$C$4:$C$112,A12,Ledger!$E$4:$E$112) | C12: =IFERROR(INDEX(Settings!$B$5:$B$18,MATCH(A12,Settings!$A$5:$A$18,0)),0) | D12: =SUMIF(Ledger!$C$4:$C$112,A12,Ledger!$H$4:$H$112)
A13: Mortgage | B13: =SUMIF(Ledger!$C$4:$C$112,A13,Ledger!$E$4:$E$112) | C13: =IFERROR(INDEX(Settings!$B$5:$B$18,MATCH(A13,Settings!$A$5:$A$18,0)),0) | D13: =SUMIF(Ledger!$C$4:$C$112,A13,Ledger!$H$4:$H$112)
A14: Moving/Household | B14: =SUMIF(Ledger!$C$4:$C$112,A14,Ledger!$E$4:$E$112) | C14: =IFERROR(INDEX(Settings!$B$5:$B$18,MATCH(A14,Settings!$A$5:$A$18,0)),0) | D14: =SUMIF(Ledger!$C$4:$C$112,A14,Ledger!$H$4:$H$112)
A15: Construction & Home Improvements | B15: =SUMIF(Ledger!$C$4:$C$112,A15,Ledger!$E$4:$E$112) | C15: =IFERROR(INDEX(Settings!$B$5:$B$18,MATCH(A15,Settings!$A$5:$A$18,0)),0) | D15: =SUMIF(Ledger!$C$4:$C$112,A15,Ledger!$H$4:$H$112)
A16: Labor | B16: =SUMIF(Ledger!$C$4:$C$112,A16,Ledger!$E$4:$E$112) | C16: =IFERROR(INDEX(Settings!$B$5:$B$18,MATCH(A16,Settings!$A$5:$A$18,0)),0) | D16: =SUMIF(Ledger!$C$4:$C$112,A16,Ledger!$H$4:$H$112)
A17: Home Repairs & A/C | B17: =SUMIF(Ledger!$C$4:$C$112,A17,Ledger!$E$4:$E$112) | C17: =IFERROR(INDEX(Settings!$B$5:$B$18,MATCH(A17,Settings!$A$5:$A$18,0)),0) | D17: =SUMIF(Ledger!$C$4:$C$112,A17,Ledger!$H$4:$H$112)
A18: Advances to Lindsey | B18: =SUMIF(Ledger!$C$4:$C$112,A18,Ledger!$E$4:$E$112) | C18: =IFERROR(INDEX(Settings!$B$5:$B$18,MATCH(A18,Settings!$A$5:$A$18,0)),0) | D18: =SUMIF(Ledger!$C$4:$C$112,A18,Ledger!$H$4:$H$112)
A19: Subtotal (she owes) | D19: =SUM(D5:D18)
A20: Less: money you already paid Lindsey | D20: =-IF(Settings!$B$20="Yes",'Credits (Paid to Lindsey)'!$C$4,0)
A21: NET — LINDSEY OWES YOU | D21: =D19+D20
A23: How this is calculated:
A24: • Each bill was read from the folder; utility bills use the current-period charge (past-due balances excluded so nothing double-counts).
A25: • Percentages are set on the Settings tab — change them there and every number updates.
A26: • School/tuition and medical default to 12%; household costs to 50%.
A27: • Tuition invoices are treated as paid; duplicate files and partial-payment receipts are listed on the Review tab, not counted twice.
A28: • Direct support to Eli (~$7,700) and child support (~$1,100/mo through 5/1/2026) are excluded from this claim and noted for the record. See the Review tab for other items intentionally excluded (duplicates, business items you flagged, unpaid balances).

Sheet Settings
A1: Reimbursement Settings — edit the yellow cells; every sheet recalculates automatically
A3: Percentage Lindsey reimburses, by category
A4: Category | B4: % She Owes
A5: Utilities | B5: 0.5
A6: Pool | B6: 0.5
A7: Storage | B7: 0.5
A8: Cleaning | B8: 0.5
A9: Lawn/Yard | B9: 0.5
A10: AT&T Business | B10: 0
A11: School/Tuition | B11: 0.12
A12: Medical/Dental/Vision | B12: 0.12
A13: Mortgage | B13: 0.5
A14: Moving/Household | B14: 0.8
A15: Construction & Home Improvements | B15: 0.5
A16: Labor | B16: 0.5
... A18: Advances to Lindsey | B18: 1
A20: Subtract money you already paid Lindsey (Venmo credits)? | B20: No
A22: Notes: Household/utilities default 50%. School/tuition & medical default 12% (per your agreement).
A23: “Treat all bills as paid” is ON: tuition invoices are counted as paid; duplicate/partial receipts are not double-counted.

Sheet Ledger
A1: Itemized Ledger — every bill, by date
A3: Date | B3: Vendor | C3: Category | D3: Description | E3: Amount | F3: Counted | G3: % She Owes | H3: Her Share | I3: Source File | J3: Notes
A4: 2024-08-01 | B4: Assurance Financial | C4: Mortgage | D4: Home mortgage (8792 W Fairway Dr) - Assurance Financial, actual amounts from payment notices | E4: 3675.19 | F4: Yes | G4: =IFERROR(INDEX(Settings!$B$5:$B$18,MATCH(C4,Settings!$A$5:$A$18,0)),0) | H4: =IF(F4="Yes",ROUND(E4*G4,2),0) | I4: (from Assurance payment notices - email) | J4: mortgage (actual)
A5: 2024-08-09 | B5: BR Water | C5: Utilities | D5: Water/Sewer Aug 2024 (SpeedPay payment, acct *2506) | E5: 281.73 | F5: Yes | G5: =IFERROR(INDEX(Settings!$B$5:$B$18,MATCH(C5,Settings!$A$5:$A$18,0)),0) | H5: =IF(F5="Yes",ROUND(E5*G5,2),0) | I5: (from Gmail sweep 2026-07-18) | J5: email-sourced
A6: 2024-08-12 | B6: Atmos (Gas) | C6: Utilities | D6: from email (current charges) | E6: 84.2 | F6: Yes | G6: =IFERROR(INDEX(Settings!$B$5:$B$18,MATCH(C6,Settings!$A$5:$A$18,0)),0) | H6: =IF(F6="Yes",ROUND(E6*G6,2),0) | I6: (from Gmail sweep 2026-07-18) | J6: email-sourced
A7: 2024-08-22 | B7: AT&T Business (Pearsons Luggage) | C7: AT&T Business | D7: Her portion of shared wireless plan (family bill) | E7: 100 | F7: Yes | G7: flat $100 | H7: 100 | I7: (shared family wireless plan - statement available on request) | J7: email-sourced | $100/mo portion per agreement
A8: 2024-08-31 | B8: AT&T Internet | C8: Utilities | D8: from email | E8: 110.38 | F8: Yes | G8: =IFERROR(INDEX(Settings!$B$5:$B$18,MATCH(C8,Settings!$A$5:$A$18,0)),0) | H8: =IF(F8="Yes",ROUND(E8*G8,2),0) | I8: (from Gmail sweep 2026-07-18) | J8: email-sourced
A9: 2024-09-01 | B9: Assurance Financial | C9: Mortgage | D9: Home mortgage (8792 W Fairway Dr) - Assurance Financial, actual amounts from payment notices | E9: 3675.19 | F9: Yes | G9: =IFERROR(INDEX(Settings!$B$5:$B$18,MATCH(C9,Settings!$A$5:$A$18,0)),0) | H9: =IF(F9="Yes",ROUND(E9*G9,2),0) | I9: (from Assurance payment notices - email) | J9: mortgage (actual)
A10: 2024-09-07 | B10: Entergy (Electric) | C10: Utilities | D10: from email - no PDF on file | E10: 522.76 | F10: Yes | G10: =IFERROR(INDEX(Settings!$B$5:$B$18,MATCH(C10,Settings!$A$5:$A$18,0)),0) | H10: =IF(F10="Yes",ROUND(E10*G10,2),0) | I10: (from Gmail sweep 2026-07-18) | J10: email-sourced
A11: 2024-09-11 | B11: Atmos (Gas) | C11: Utilities | D11: from email (current charges) | E11: 36.94 | F11: Yes | G11: =IFERROR(INDEX(Settings!$B$5:$B$18,MATCH(C11,Settings!$A$5:$A$18,0)),0) | H11: =IF(F11="Yes",ROUND(E11*G11,2),0) | I11: (from Gmail sweep 2026-07-18) | J11: email-sourced
A12: 2024-09-16 | B12: St Luke's School (FACTS) | C12: School/Tuition | D12: Class trips 2024-25 (FACTS conf, MC 6499) | E12: 200 | F12: Yes | G12: =IFERROR(INDEX(Settings!$B$5:$B$18,MATCH(C12,Settings!$A$5:$A$18,0)),0) | H12: =IF(F12="Yes",ROUND(E12*G12,2),0) | I12: (from Gmail sweep 2026-07-18) | J12: email-sourced
A13: 2024-09-18 | B13: Pool (Fernando) | C13: Pool | D13: Pool service Aug 2024, inv#2119 (paid by Venmo 9/18/24; predates James-pool series) | E13: 356 | F13: Yes | G13: =IFERROR(INDEX(Settings!$B$5:$B$18,MATCH(C13,Settings!$A$5:$A$18,0)),0) | H13: =IF(F13="Yes",ROUND(E13*G13,2),0) | I13: (from Gmail sweep 2026-07-18) | J13: email-sourced
A14: 2024-09-22 | B14: AT&T Business (Pearsons Luggage) | C14: AT&T Business | D14: Her portion of shared wireless plan (family bill) | E14: 100 | F14: Yes | G14: flat $100 | H14: 100 | I14: (shared family wireless plan - statement available on request) | J14: email-sourced | $100/mo portion per agreement
A15: 2024-09-30 | B15: AT&T Internet | C15: Utilities | D15: from email | E15: 110.38 | F15: Yes | G15: =IFERROR(INDEX(Settings!$B$5:$B$18,MATCH(C15,Settings!$A$5:$A$18,0)),0) | H15: =IF(F15="Yes",ROUND(E15*G15,2),0) | I15: (from Gmail sweep 2026-07-18) | J15: email-sourced
A16: 2024-10-01 | B16: Assurance Financial | C16: Mortgage | D16: Home mortgage (8792 W Fairway Dr) - Assurance Financial, actual amounts from payment notices | E16: 3675.19 | F16: Yes | G16: =IFERROR(INDEX(Settings!$B$5:$B$18,MATCH(C16,Settings!$A$5:$A$18,0)),0) | H16: =IF(F16="Yes",ROUND(E16*G16,2),0) | I16: (from Assurance payment notices - email) | J16: mortgage (actual)
A17: 2024-10-04 | B17: Pool (Fernando) | C17: Pool | D17: inv#2178 from email | E17: 443 | F17: Yes | G17: =IFERROR(INDEX(Settings!$B$5:$B$18,MATCH(C17,Settings!$A$5:$A$18,0)),0) | H17: =IF(F17="Yes",ROUND(E17*G17,2),0) | I17: (from Gmail sweep 2026-07-18) | J17: email-sourced
A18: 2024-10-06 | B18: St Luke's School (FACTS) | C18: School/Tuition | D18: Parents' Guild merchandise (FACTS conf) | E18: 18 | F18: Yes | G18: =IFERROR(INDEX(Settings!$B$5:$B$18,MATCH(C18,Settings!$A$5:$A$18,0)),0) | H18: =IF(F18="Yes",ROUND(E18*G18,2),0) | I18: (from Gmail sweep 2026-07-18) | J18: email-sourced
A19: 2024-10-10 | B19: Atmos (Gas) | C19: Utilities | D19: from email (current charges) | E19: 59.81 | F19: Yes | G19: =IFERROR(INDEX(Settings!$B$5:$B$18,MATCH(C19,Settings!$A$5:$A$18,0)),0) | H19: =IF(F19="Yes",ROUND(E19*G19,2),0) | I19: (from Gmail sweep 2026-07-18) | J19: email-sourced
A20: 2024-10-14 | B20: St Luke's School (FACTS) | C20: School/Tuition | D20: Class trips 2024-25 (FACTS conf, Visa 8056) | E20: 200 | F20: Yes | G20: =IFERROR(INDEX(Settings!$B$5:$B$18,MATCH(C20,Settings!$A$5:$A$18,0)),0) | H20: =IF(F20="Yes",ROUND(E20*G20,2),0) | I20: (from Gmail sweep 2026-07-18) | J20: email-sourced
A21: 2024-10-22 | B21: AT&T Business (Pearsons Luggage) | C21: AT&T Business | D21: Her portion of shared wireless plan (family bill) | E21: 100 | F21: Yes | G21: flat $100 | H21: 100 | I21: (shared family wireless plan - statement available on request) | J21: email-sourced | $100/mo portion per agreement
A22: 2024-10-30 | B22: AT&T Internet | C22: Utilities | D22: from email | E22: 110.38 | F22: Yes | G22: =IFERROR(INDEX(Settings!$B$5:$B$18,MATCH(C22,Settings!$A$5:$A$18,0)),0) | H22: =IF(F22="Yes",ROUND(E22*G22,2),0) | I22: (from Gmail sweep 2026-07-18) | J22: email-sourced
A23: 2024-11-01 | B23: Assurance Financial | C23: Mortgage | D23: Home mortgage (8792 W Fairway Dr) - Assurance Financial, actual amounts from payment notices | E23: 3675.19 | F23: Yes | G23: =IFERROR(INDEX(Settings!$B$5:$B$18,MATCH(C23,Settings!$A$5:$A$18,0)),0) | H23: =IF(F23="Yes",ROUND(E23*G23,2),0) | I23: (from Assurance payment notices - email) | J23: mortgage (actual)
A24: 2024-11-04 | B24: Pool (Fernando) | C24: Pool | D24: inv#2234 from email | E24: 356 | F24: Yes | G24: =IFERROR(INDEX(Settings!$B$5:$B$18,MATCH(C24,Settings!$A$5:$A$18,0)),0) | H24: =IF(F24="Yes",ROUND(E24*G24,2),0) | I24: (from Gmail sweep 2026-07-18) | J24: email-sourced
A25: 2024-11-09 | B25: AT&T Internet | C25: Utilities | D25: Home internet acct 310682407 (original home acct per Ned records; predecessor of 322444580) | E25: 80.92 | F25: Yes | G25: =IFERROR(INDEX(Settings!$B$5:$B$18,MATCH(C25,Settings!$A$5:$A$18,0)),0) | H25: =IF(F25="Yes",ROUND(E25*G25,2),0) | I25: (from Gmail sweep 2026-07-18) | J25: email-sourced
A26: 2024-11-11 | B26: Atmos (Gas) | C26: Utilities | D26: from email (current charges) | E26: 53.16 | F26: Yes | G26: =IFERROR(INDEX(Settings!$B$5:$B$18,MATCH(C26,Settings!$A$5:$A$18,0)),0) | H26: =IF(F26="Yes",ROUND(E26*G26,2),0) | I26: (from Gmail sweep 2026-07-18) | J26: email-sourced
A27: 2024-11-22 | B27: AT&T Business (Pearsons Luggage) | C27: AT&T Business | D27: Her portion of shared wireless plan (family bill) | E27: 100 | F27: Yes | G27: flat $100 | H27: 100 | I27: (shared family wireless plan - statement available on request) | J27: email-sourced | $100/mo portion per agreement
A28: 2024-12-01 | B28: Assurance Financial | C28: Mortgage | D28: Home mortgage (8792 W Fairway Dr) - Assurance Financial, actual amounts from payment notices | E28: 3675.19 | F28: Yes | G28: =IFERROR(INDEX(Settings!$B$5:$B$18,MATCH(C28,Settings!$A$5:$A$18,0)),0) | H28: =IF(F28="Yes",ROUND(E28*G28,2),0) | I28: (from Assurance payment notices - email) | J28: mortgage (actual)
A29: 2024-12-01 | B29: AT&T Internet | C29: Utilities | D29: from email | E29: 115.38 | F29: Yes | G29: =IFERROR(INDEX(Settings!$B$5:$B$18,MATCH(C29,Settings!$A$5:$A$18,0)),0) | H29: =IF(F29="Yes",ROUND(E29*G29,2),0) | I29: (from Gmail sweep 2026-07-18) | J29: email-sourced
A30: 2024-12-04 | B30: Pool (Fernando) | C30: Pool | D30: inv#2298 from email | E30: 348 | F30: Yes | G30: =IFERROR(INDEX(Settings!$B$5:$B$18,MATCH(C30,Settings!$A$5:$A$18,0)),0) | H30: =IF(F30="Yes",ROUND(E30*G30,2),0) | I30: (from Gmail sweep 2026-07-18) | J30: email-sourced
A31: 2024-12-06 | B31: Entergy (Electric) | C31: Utilities | D31: from email - no PDF on file | E31: 506.49 | F31: Yes | G31: =IFERROR(INDEX(Settings!$B$5:$B$18,MATCH(C31,Settings!$A$5:$A$18,0)),0) | H31: =IF(F31="Yes",ROUND(E31*G31,2),0) | I31: (from Gmail sweep 2026-07-18) | J31: email-sourced
A32: 2024-12-11 | B32: Atmos (Gas) | C32: Utilities | D32: from email (current charges) | E32: 63.83 | F32: Yes | G32: =IFERROR(INDEX(Settings!$B$5:$B$18,MATCH(C32,Settings!$A$5:$A$18,0)),0) | H32: =IF(F32="Yes",ROUND(E32*G32,2),0) | I32: (from Gmail sweep 2026-07-18) | J32: email-sourced
A33: 2024-12-22 | B33: AT&T Business (Pearsons Luggage) | C33: AT&T Business | D33: AT&T business 2024-12 — Lindsey's $100 portion — her portion of shared wireless plan | E33: 100 | F33: Yes | G33: flat $100 | H33: 100 | I33: (manual entry - config.json) | J33: manual
A34: 2024-12-30 | B34: AT&T Internet | C34: Utilities | D34: from email | E34: 115.38 | F34: Yes | G34: =IFERROR(INDEX(Settings!$B$5:$B$18,MATCH(C34,Settings!$A$5:$A$18,0)),0) | H34: =IF(F34="Yes",ROUND(E34*G34,2),0) | I34: (from Gmail sweep 2026-07-18) | J34: email-sourced
A35: 2025-01-01 | B35: Assurance Financial | C35: Mortgage | D35: Home mortgage (8792 W Fairway Dr) - Assurance Financial, actual amounts from payment notices | E35: 3675.19 | F35: Yes | G35: =IFERROR(INDEX(Settings!$B$5:$B$18,MATCH(C35,Settings!$A$5:$A$18,0)),0) | H35: =IF(F35="Yes",ROUND(E35*G35,2),0) | I35: (from Assurance payment notices - email) | J35: mortgage (actual)
A36: 2025-01-07 | B36: Assurance Financial | C36: Mortgage | D36: Returned-check late charges $205 + NSF fee $20 (Notice 1/7/25, addressed to both Gerald & Lindsey Pearson; $3,675.19 check returned) | E36: 225 | F36: Yes | G36: =IFERROR(INDEX(Settings!$B$5:$B$18,MATCH(C36,Settings!$A$5:$A$18,0)),0) | H36: =IF(F36="Yes",ROUND(E36*G36,2),0) | I36: (manual entry - config.json) | J36: manual
A37: 2025-01-07 | B37: Pool (Fernando) | C37: Pool | D37: inv#2375 from email | E37: 429 | F37: Yes | G37: =IFERROR(INDEX(Settings!$B$5:$B$18,MATCH(C37,Settings!$A$5:$A$18,0)),0) | H37: =IF(F37="Yes",ROUND(E37*G37,2),0) | I37: (from Gmail sweep 2026-07-18) | J37: email-sourced
A38: 2025-01-08 | B38: BR Water | C38: Utilities | D38: Water/Sewer Sep-Dec 2024 balance (catch-up payment 1/8/25, acct *2506) | E38: 361.21 | F38: Yes | G38: =IFERROR(INDEX(Settings!$B$5:$B$18,MATCH(C38,Settings!$A$5:$A$18,0)),0) | H38: =IF(F38="Yes",ROUND(E38*G38,2),0) | I38: (from Gmail sweep 2026-07-18) | J38: email-sourced
A39: 2025-01-08 | B39: BR Water | C39: Utilities | D39: Irrigation late-2024 balance (catch-up payment 1/8/25, acct *4303) | E39: 21.87 | F39: Yes | G39: =IFERROR(INDEX(Settings!$B$5:$B$18,MATCH(C39,Settings!$A$5:$A$18,0)),0) | H39: =IF(F39="Yes",ROUND(E39*G39,2),0) | I39: (from Gmail sweep 2026-07-18) | J39: email-sourced
A40: 2025-01-09 | B40: Entergy (Electric) | C40: Utilities | D40: from email - no PDF on file | E40: 511.18 | F40: Yes | G40: =IFERROR(INDEX(Settings!$B$5:$B$18,MATCH(C40,Settings!$A$5:$A$18,0)),0) | H40: =IF(F40="Yes",ROUND(E40*G40,2),0) | I40: (from Gmail sweep 2026-07-18) | J40: email-sourced
A41: 2025-01-13 | B41: Atmos (Gas) | C41: Utilities | D41: from email (current charges) | E41: 68.48 | F41: Yes | G41: =IFERROR(INDEX(Settings!$B$5:$B$18,MATCH(C41,Settings!$A$5:$A$18,0)),0) | H41: =IF(F41="Yes",ROUND(E41*G41,2),0) | I41: (from Gmail sweep 2026-07-18) | J41: email-sourced
...

Sheet Credits (Paid to Lindsey)
A1: Money you already paid Lindsey (Venmo) — subtracted from what she owes
A3: Date | B3: Description | C3: Amount | D3: Source
B4: None — advances to Lindsey are claimed as a category in the Ledger. | C4: 0

Sheet By Month
A1: Her Share by Month
A3: Month | B3: Billed Amount | C3: Her Share
A4: 2024-08 | B4: =SUMPRODUCT((LEFT(Ledger!$A$4:$A$112,7)="2024-08")*Ledger!$E$4:$E$112) | C4: =SUMPRODUCT((LEFT(Ledger!$A$4:$A$112,7)="2024-08")*Ledger!$H$4:$H$112)
A5: 2024-09 | B5: =SUMPRODUCT((LEFT(Ledger!$A$4:$A$112,7)="2024-09")*Ledger!$E$4:$E$112) | C5: =SUMPRODUCT((LEFT(Ledger!$A$4:$A$112,7)="2024-09")*Ledger!$H$4:$H$112)
A6: 2024-10 | B6: =SUMPRODUCT((LEFT(Ledger!$A$4:$A$112,7)="2024-10")*Ledger!$E$4:$E$112) | C6: =SUMPRODUCT((LEFT(Ledger!$A$4:$A$112,7)="2024-10")*Ledger!$H$4:$H$112)
A7: 2024-11 | B7: =SUMPRODUCT((LEFT(Ledger!$A$4:$A$112,7)="2024-11")*Ledger!$E$4:$E$112) | C7: =SUMPRODUCT((LEFT(Ledger!$A$4:$A$112,7)="2024-11")*Ledger!$H$4:$H$112)
A8: 2024-12 | B8: =SUMPRODUCT((LEFT(Ledger!$A$4:$A$112,7)="2024-12")*Ledger!$E$4:$E$112) | C8: =SUMPRODUCT((LEFT(Ledger!$A$4:$A$112,7)="2024-12")*Ledger!$H$4:$H$112)
A9: 2025-01 | B9: =SUMPRODUCT((LEFT(Ledger!$A$4:$A$112,7)="2025-01")*Ledger!$E$4:$E$112) | C9: =SUMPRODUCT((LEFT(Ledger!$A$4:$A$112,7)="2025-01")*Ledger!$H$4:$H$112)
A10: 2025-02 | B10: =SUMPRODUCT((LEFT(Ledger!$A$4:$A$112,7)="2025-02")*Ledger!$E$4:$E$112) | C10: =SUMPRODUCT((LEFT(Ledger!$A$4:$A$112,7)="2025-02")*Ledger!$H$4:$H$112)
A11: 2025-03 | B11: =SUMPRODUCT((LEFT(Ledger!$A$4:$A$112,7)="2025-03")*Ledger!$E$4:$E$112) | C11: =SUMPRODUCT((LEFT(Ledger!$A$4:$A$112,7)="2025-03")*Ledger!$H$4:$H$112)
A12: 2025-04 | B12: =SUMPRODUCT((LEFT(Ledger!$A$4:$A$112,7)="2025-04")*Ledger!$E$4:$E$112) | C12: =SUMPRODUCT((LEFT(Ledger!$A$4:$A$112,7)="2025-04")*Ledger!$H$4:$H$112)
A13: 2025-05 | B13: =SUMPRODUCT((LEFT(Ledger!$A$4:$A$112,7)="2025-05")*Ledger!$E$4:$E$112) | C13: =SUMPRODUCT((LEFT(Ledger!$A$4:$A$112,7)="2025-05")*Ledger!$H$4:$H$112)
A14: 2025-06 | B14: =SUMPRODUCT((LEFT(Ledger!$A$4:$A$112,7)="2025-06")*Ledger!$E$4:$E$112) | C14: =SUMPRODUCT((LEFT(Ledger!$A$4:$A$112,7)="2025-06")*Ledger!$H$4:$H$112)
A15: 2025-07 | B15: =SUMPRODUCT((LEFT(Ledger!$A$4:$A$112,7)="2025-07")*Ledger!$E$4:$E$112) | C15: =SUMPRODUCT((LEFT(Ledger!$A$4:$A$112,7)="2025-07")*Ledger!$H$4:$H$112)
A16: 2025-08 | B16: =SUMPRODUCT((LEFT(Ledger!$A$4:$A$112,7)="2025-08")*Ledger!$E$4:$E$112) | C16: =SUMPRODUCT((LEFT(Ledger!$A$4:$A$112,7)="2025-08")*Ledger!$H$4:$H$112)
A17: 2025-09 | B17: =SUMPRODUCT((LEFT(Ledger!$A$4:$A$112,7)="2025-09")*Ledger!$E$4:$E$112) | C17: =SUMPRODUCT((LEFT(Ledger!$A$4:$A$112,7)="2025-09")*Ledger!$H$4:$H$112)
A18: 2025-10 | B18: =SUMPRODUCT((LEFT(Ledger!$A$4:$A$112,7)="2025-10")*Ledger!$E$4:$E$112) | C18: =SUMPRODUCT((LEFT(Ledger!$A$4:$A$112,7)="2025-10")*Ledger!$H$4:$H$112)
A19: 2025-11 | B19: =SUMPRODUCT((LEFT(Ledger!$A$4:$A$112,7)="2025-11")*Ledger!$E$4:$E$112) | C19: =SUMPRODUCT((LEFT(Ledger!$A$4:$A$112,7)="2025-11")*Ledger!$H$4:$H$112)
A20: 2025-12 | B20: =SUMPRODUCT((LEFT(Ledger!$A$4:$A$112,7)="2025-12")*Ledger!$E$4:$E$112) | C20: =SUMPRODUCT((LEFT(Ledger!$A$4:$A$112,7)="2025-12")*Ledger!$H$4:$H$112)
A21: 2026-01 | B21: =SUMPRODUCT((LEFT(Ledger!$A$4:$A$112,7)="2026-01")*Ledger!$E$4:$E$112) | C21: =SUMPRODUCT((LEFT(Ledger!$A$4:$A$112,7)="2026-01")*Ledger!$H$4:$H$112)
A22: 2026-02 | B22: =SUMPRODUCT((LEFT(Ledger!$A$4:$A$112,7)="2026-02")*Ledger!$E$4:$E$112) | C22: =SUMPRODUCT((LEFT(Ledger!$A$4:$A$112,7)="2026-02")*Ledger!$H$4:$H$112)
A23: 2026-03 | B23: =SUMPRODUCT((LEFT(Ledger!$A$4:$A$112,7)="2026-03")*Ledger!$E$4:$E$112) | C23: =SUMPRODUCT((LEFT(Ledger!$A$4:$A$112,7)="2026-03")*Ledger!$H$4:$H$112)
A24: 2026-04 | B24: =SUMPRODUCT((LEFT(Ledger!$A$4:$A$112,7)="2026-04")*Ledger!$E$4:$E$112) | C24: =SUMPRODUCT((LEFT(Ledger!$A$4:$A$112,7)="2026-04")*Ledger!$H$4:$H$112)
A25: 2026-05 | B25: =SUMPRODUCT((LEFT(Ledger!$A$4:$A$112,7)="2026-05")*Ledger!$E$4:$E$112) | C25: =SUMPRODUCT((LEFT(Ledger!$A$4:$A$112,7)="2026-05")*Ledger!$H$4:$H$112)
A26: 2026-06 | B26: =SUMPRODUCT((LEFT(Ledger!$A$4:$A$112,7)="2026-06")*Ledger!$E$4:$E$112) | C26: =SUMPRODUCT((LEFT(Ledger!$A$4:$A$112,7)="2026-06")*Ledger!$H$4:$H$112)
A27: 2026-07 | B27: =SUMPRODUCT((LEFT(Ledger!$A$4:$A$112,7)="2026-07")*Ledger!$E$4:$E$112) | C27: =SUMPRODUCT((LEFT(Ledger!$A$4:$A$112,7)="2026-07")*Ledger!$H$4:$H$112)
A28: 2026-08 | B28: =SUMPRODUCT((LEFT(Ledger!$A$4:$A$112,7)="2026-08")*Ledger!$E$4:$E$112) | C28: =SUMPRODUCT((LEFT(Ledger!$A$4:$A$112,7)="2026-08")*Ledger!$H$4:$H$112)
A29: TOTAL | B29: =SUM(B4:B28) | C29: =SUM(C4:C28)

Sheet Review (Excluded)
A1: Items reviewed but NOT counted (duplicates, invoices already paid, unpaid balances)
A2: Shown for full transparency. Nothing here is added to the total.
A4: Date | B4: Vendor | C4: Category | D4: Description | E4: Amount | F4: Why excluded | G4: Source File
A5: 2026-06-24 | B5: AT&T Business (Pearsons Luggage) | C5: AT&T Business | D5: Her portion of shared wireless plan (family bill) | E5: 100 | F5: email-sourced | $100/mo portion per agreement | after AT&T end 2026-05 | before Aug 2024 cutoff | G5: (shared family wireless plan - statement available on request)
A6: 2026-07-22 | B6: AT&T Business (Pearsons Luggage) | C6: AT&T Business | D6: Her portion of shared wireless plan (family bill) | E6: 100 | F6: email-sourced | $100/mo portion per agreement | after AT&T end 2026-05 | before Aug 2024 cutoff | G6: (shared family wireless plan - statement available on request)
B7: ? | C7: NEEDS REVIEW | D7: UNRECOGNIZED - please categorize | F7: auto-detect failed | G7: demo.pdf
B8: ? | C8: NEEDS REVIEW | D8: UNRECOGNIZED - please categorize | F8: auto-detect failed | G8: demo_docs\vol1.pdf
B9: ? | C9: NEEDS REVIEW | D9: UNRECOGNIZED - please categorize | F9: auto-detect failed | G9: demo_docs\vol2.pdf
B10: ? | C10: NEEDS REVIEW | D10: UNRECOGNIZED - please categorize | F10: auto-detect failed | G10: demo_docs\vol3.pdf
B11: ? | C11: NEEDS REVIEW | D11: UNRECOGNIZED - please categorize | E11: 275 | F11: auto-detect failed | G11: docs\proof\Cleaning.pdf
B12: ? | C12: NEEDS REVIEW | D12: UNRECOGNIZED - please categorize | E12: 10300 | F12: auto-detect failed | G12: docs\proof\ConstructionHomeImprovements.pdf
B13: ? | C13: NEEDS REVIEW | D13: UNRECOGNIZED - please categorize | E13: 3600 | F13: auto-detect failed | G13: docs\proof\HomeRepairsAC.pdf
B14: ? | C14: NEEDS REVIEW | D14: UNRECOGNIZED - please categorize | E14: 3100 | F14: auto-detect failed | G14: docs\proof\Labor.pdf
B15: ? | C15: NEEDS REVIEW | D15: UNRECOGNIZED - please categorize | E15: 3917.74 | F15: auto-detect failed | G15: docs\proof\Mortgage.pdf
B16: ? | C16: NEEDS REVIEW | D16: UNRECOGNIZED - please categorize | E16: 1600 | F16: auto-detect failed | G16: docs\proof\MovingHousehold.pdf
B17: ? | C17: NEEDS REVIEW | D17: UNRECOGNIZED - please categorize | E17: 330.75 | F17: auto-detect failed | G17: docs\proof\Storage.pdf
B18: Pool (Fernando) | C18: Pool | D18: Pool service inv#? | E18: 0 | F18: no date/amount readable - moved to Review | G18: docs\proof\Pool.pdf
B19: Pool (Fernando) | C19: Pool | D19: Pool service inv#? | E19: 0 | F19: no date/amount readable - moved to Review | G19: docs\proof\vol2.pdf
A20: 2025-01-25 | B20: Pool (Fernando) — James pool | C20: Pool | D20: inv#2319 - JAMES POOL, not the Fairway house | E20: 280 | F20: James pool - excluded per Ned | G20: (from Gmail sweep 2026-07-18)
A21: 2025-02-25 | B21: Pool (Fernando) — James pool | C21: Pool | D21: inv#2450 - JAMES POOL, not the Fairway house | E21: 350 | F21: James pool - excluded per Ned | G21: (from Gmail sweep 2026-07-18)
A22: 2025-03-14 | B22: Pool (Fernando) — James pool | C22: Pool | D22: inv#2507 - JAMES POOL, not the Fairway house | E22: 280 | F22: James pool - excluded per Ned | G22: (from Gmail sweep 2026-07-18)
A23: 2025-06-10 | B23: Pool (Fernando) — James pool | C23: Pool | D23: inv#2625 - JAMES POOL, not the Fairway house | E23: 280 | F23: James pool - excluded per Ned | G23: (from Gmail sweep 2026-07-18)
A24: 2025-06-10 | B24: Pool (Fernando) — James pool | C24: Pool | D24: inv#2698 - JAMES POOL, not the Fairway house | E24: 350 | F24: James pool - excluded per Ned | G24: (from Gmail sweep 2026-07-18)
A25: 2025-07-03 | B25: Pool (Fernando) — James pool | C25: Pool | D25: inv#2766 - JAMES POOL, not the Fairway house | E25: 280 | F25: James pool - excluded per Ned | G25: (from Gmail sweep 2026-07-18)
A26: 2025-08-14 | B26: Pool (Fernando) — James pool | C26: Pool | D26: inv#2836 - JAMES POOL, not the Fairway house | E26: 350 | F26: James pool - excluded per Ned | G26: (from Gmail sweep 2026-07-18)
A27: 2025-09-08 | B27: Pool (Fernando) — James pool | C27: Pool | D27: inv#2911 - JAMES POOL, not the Fairway house | E27: 280 | F27: James pool - excluded per Ned | G27: (from Gmail sweep 2026-07-18)
A28: 2025-10-14 | B28: Pool (Fernando) — James pool | C28: Pool | D28: inv#3008 - JAMES POOL, not the Fairway house | E28: 280 | F28: James pool - excluded per Ned | G28: (from Gmail sweep 2026-07-18)
A29: 2025-11-06 | B29: Pool (Fernando) — James pool | C29: Pool | D29: inv#3048 - JAMES POOL, not the Fairway house | E29: 350 | F29: James pool - excluded per Ned | G29: (from Gmail sweep 2026-07-18)
A30: 2025-12-01 | B30: Pool (Fernando) — James pool | C30: Pool | D30: inv#3134 - JAMES POOL, not the Fairway house | E30: 280 | F30: James pool - excluded per Ned | G30: (from Gmail sweep 2026-07-18)
A31: 2026-01-05 | B31: Pool (Fernando) — James pool | C31: Pool | D31: inv#3189 - JAMES POOL, not the Fairway house | E31: 350 | F31: James pool - excluded per Ned | G31: (from Gmail sweep 2026-07-18)
B32: St Luke's School (FACTS) | C32: School/Tuition | D32: Tuition payment — paid by Gerald Pearson | F32: no date/amount readable - moved to Review | G32: docs\proof\SchoolTuition.pdf
B33: Atmos (Gas) | C33: Utilities | D33: Gas current charges | F33: no date/amount readable - moved to Review | G33: docs\proof\Utilities.pdf
B34: Atmos (Gas) | C34: Utilities | D34: Gas current charges | F34: no date/amount readable - moved to Review | G34: docs\proof\vol1.pdf
A35: 2026-05-07 | B35: Entergy (Electric) | C35: Utilities | D35: Electric current charges (bill 5/7/26; total due incl. arrears excluded) | E35: 347 | F35: email-sourced | after utilities end 2026-04 | before Aug 2024 cutoff | G35: (from Gmail sweep 2026-07-18)
A36: 2026-05-12 | B36: Atmos (Gas) | C36: Utilities | D36: from email (current charges) | E36: 41.88 | F36: email-sourced | after utilities end 2026-04 | before Aug 2024 cutoff | G36: (from Gmail sweep 2026-07-18)
A37: 2026-05-12 | B37: BR Water | C37: Utilities | D37: Irrigation Apr+May 2026 (autopay 5/12/26) | E37: 62.36 | F37: email-sourced | after utilities end 2026-04 | before Aug 2024 cutoff | G37: (from Gmail sweep 2026-07-18)
A38: 2026-05-31 | B38: AT&T Internet | C38: Utilities | D38: from email | E38: 160.42 | F38: email-sourced | after utilities end 2026-04 | before Aug 2024 cutoff | G38: (from Gmail sweep 2026-07-18)
A39: 2026-06-06 | B39: Entergy (Electric) | C39: Utilities | D39: Electric current charges (bill 6/6/26) | E39: 435.76 | F39: email-sourced | after utilities end 2026-04 | before Aug 2024 cutoff | G39: (from Gmail sweep 2026-07-18)
A40: 2026-06-09 | B40: BR Water | C40: Utilities | D40: Irrigation Jun 2026 (autopay) | E40: 18.94 | F40: email-sourced | after utilities end 2026-04 | before Aug 2024 cutoff | G40: (from Gmail sweep 2026-07-18)
A41: 2026-06-10 | B41: Atmos (Gas) | C41: Utilities | D41: from email (current charges) | E41: 57.46 | F41: email-sourced | after utilities end 2026-04 | before Aug 2024 cutoff | G41: (from Gmail sweep 2026-07-18)
...

Sheet Missing Bills
A1: Missing Bills — months with no bill on file (Aug 2024 – Jul 2026)
A2: Collect these and drop them in the folder, then re-run. "started" = first bill on file for that account.
A4: Bill / account | B4: On file | C4: First on file | D4: Missing months (need to collect)
A5: Atmos (Gas) | B5: 11/24 | C5: 2024-08 | D5: 2025-02, 2025-03, 2025-04, 2025-05, 2025-06, 2025-08, 2025-09, 2025-10, 2025-11, 2025-12, 2026-01, 2026-02, 2026-03
A6: Entergy (Electric) | B6: 7/24 | C6: 2024-09 | D6: 2024-08, 2024-10, 2024-11, 2025-02, 2025-03, 2025-04, 2025-05, 2025-06, 2025-07, 2025-08, 2025-09, 2025-10, 2025-11, 2025-12, 2026-01, 2026-02, 2026-03
A7: AT&T Internet | B7: 10/24 | C7: 2024-08 | D7: 2025-03, 2025-04, 2025-05, 2025-06, 2025-07, 2025-08, 2025-09, 2025-10, 2025-11, 2025-12, 2026-01, 2026-02, 2026-04, 2026-07
A8: BR Water — main | B8: 7/24 | C8: 2024-08 | D8: 2024-09, 2024-10, 2024-11, 2024-12, 2025-06, 2025-07, 2025-08, 2025-09, 2025-10, 2025-11, 2025-12, 2026-01, 2026-02, 2026-03, 2026-04, 2026-05, 2026-06
A9: BR Water — irrigation | B9: 4/24 | C9: 2025-01 | D9: 2024-08, 2024-09, 2024-10, 2024-11, 2024-12, 2025-02, 2025-03, 2025-04, 2025-05, 2025-06, 2025-07, 2025-08, 2025-09, 2025-10, 2025-11, 2025-12, 2026-01, 2026-02, 2026-03, 2026-04
A10: Pool (Fernando) | B10: 8/24 | C10: 2024-09 | D10: 2024-08, 2025-02, 2025-03, 2025-04, 2025-05, 2025-06, 2025-07, 2025-09, 2025-10, 2025-11, 2025-12, 2026-01, 2026-02, 2026-03, 2026-04, 2026-07
A11: PODS (Storage) | B11: 4/24 | C11: 2026-02 | D11: 2024-08, 2024-09, 2024-10, 2024-11, 2024-12, 2025-01, 2025-02, 2025-03, 2025-04, 2025-05, 2025-06, 2025-07, 2025-08, 2025-09, 2025-10, 2025-11, 2025-12, 2026-01, 2026-06, 2026-07
A12: AT&T Business | B12: 22/24 | C12: 2024-08 | D12: 2026-01, 2026-02
A14: Note: bills dated the month AFTER service are normal; “missing” means no statement at all for that period.
